const Album = require("../models/album.model");

exports.Create = async (req, res) => {
    try {

    } catch (error){
        console.log("error");
        return res.status(500).json({
            error: true,
            message: "Une erreur interne est survenue, veuillez réessayer plus tard."
        })
    }
}

exports.GetAll = async (req, res) => {
    try {
        const albums = await Album.findAll();

        const formattedAlbum = [];

        albums.forEach((album) => {
            formattedAlbum.push({ name: album.name, thumbnail: album.thumbnail })
        });

        return res.status(200).json({
            error: false,
            message: "Les albums ont bien été récupérés",
            data: formattedAlbum
        })
    } catch (error){
        console.log("error");
        return res.status(500).json({
            error: true,
            message: "Une erreur interne est survenue, veuillez réessayer plus tard."
        })
    }
}

exports.GetById = async (req, res) => {
    try {
        const { id } = req.params;

        if (!id || isNaN(id)) {
            return res.status(400).json({
                error: true,
                message: "Requête invalide."
            });
        }

        const album = await Album.findOne({ where: { id: id } });

        if (!album) {
            return res.status(404).json({
                error: true,
                message: "L'album est introuvable."
            });
        }

        return res.status(200).json({
            error: false,
            message: "L'album a été récupéré.",
            post: album
        });
    } catch (error){
        console.log("error");
        return res.status(500).json({
            error: true,
            message: "Une erreur interne est survenue, veuillez réessayer plus tard."
        })
    }
}

exports.Update = async (req, res) => {
    try {

    } catch (error){
        console.log("error");
        return res.status(500).json({
            error: true,
            message: "Une erreur interne est survenue, veuillez réessayer plus tard."
        })
    }
}

exports.Delete = async (req, res) => {
    try {

    } catch (error){
        console.log("error");
        return res.status(500).json({
            error: true,
            message: "Une erreur interne est survenue, veuillez réessayer plus tard."
        })
    }
}