const Role = require("../models/role.model");

exports.Create = async (req, res) => {
    try {

    } catch (error){
        console.log("error");
        return res.status(500).json({
            error: true,
            message: "Une erreur interne est survenue, veuillez réessayer plus tard."
        })
    }
}

exports.GetAll = async (req, res) => {
    try {
        const roles = await Role.findAll();

        const formattedRoles = [];

        roles.forEach((role) => {
            formattedRoles.push({ name: role.name, label: role.label })
        });

        return res.status(200).json({
            error: false,
            message: "Les rôles ont bien été récupérés",
            data: formattedRoles
        })
    } catch (error){
        console.log("error");
        return res.status(500).json({
            error: true,
            message: "Une erreur interne est survenue, veuillez réessayer plus tard."
        })
    }
}

exports.GetById = async (req, res) => {
    try {

    } catch (error){
        console.log("error");
        return res.status(500).json({
            error: true,
            message: "Une erreur interne est survenue, veuillez réessayer plus tard."
        })
    }
}

exports.Update = async (req, res) => {
    try {

    } catch (error){
        console.log("error");
        return res.status(500).json({
            error: true,
            message: "Une erreur interne est survenue, veuillez réessayer plus tard."
        })
    }
}

exports.Delete = async (req, res) => {
    try {

    } catch (error){
        console.log("error");
        return res.status(500).json({
            error: true,
            message: "Une erreur interne est survenue, veuillez réessayer plus tard."
        })
    }
}